Workbook

Sheet Dashboard
C1: KPI PERFORMANCE DASHBOARD
C2: Period : Feb 2024 – Oct 2025
C4: KPI OVERVIEW
C6: TOTAL PROJECTS | G6: TOTAL TASKS | K6: Completed Task | O6: Completed Project | S6: OVER-BUDGET TASKS | W6: TASK COMPLETION %
C7: ='Data Model'!C4 -> 100 | G7: ='Data Model'!C5 -> 300 | K7: ='Data Model'!C12 -> 87 | O7: 26 | S7: ='Data Model'!C11 -> 7 | W7: ='Data Model'!C39 -> 0.29
C8: Across Portfolio | G8: work items tracked | K8: 29% Task Completed | O8: 26% Project Completed | S8: cost-control watchlist | W8: tasks fully complete
C10: EARNED VALUE | G10: AVG PROGRESS | K10: AVG DURATION | O10: HOURS LOGGED | S10: TASKS BILLED | W10: PORTFOLIO CPI
C11: ='Data Model'!C40 -> 1085090.2 | G11: ='Data Model'!C9 -> 0.63606667 | K11: ='Data Model'!C36 -> 148.47 | O11: ='Data Model'!C10 -> 5763 | S11: ='Data Model'!C37 -> 93 | W11: ='Data Model'!C39 -> 0.29
C12: value of work performed | G12: mean task completion | K12: planned task length | O12: Total Effort | S12: of 300 have actuals | W12: earned value / actual
C14: TOTAL BUDGET | G14: BUDGET UTILIZATION | K14: ACTUAL SPEND | O14: BUDGET AT RISK | S14: ON-BUDGET RATE | W14: COST VARIANCE
C15: ='Data Model'!C6 -> 1687280 | G15: ='Data Model'!C8 -> 0.3072525 | K15: ='Data Model'!C7 -> 518421 | O15: ='Data Model'!C35 -> 16457 | S15: ='Data Model'!C38 -> 0.92473118 | W15: ='Data Model'!C34 -> 5084
C16: allocated funds | G16: spend vs budget | K16: committed to date | O16: overrun across 7 tasks | S16: billed tasks within budget | W16: favorable vs budget
C18: PERFORMANCE OVERVIEW
C102: Status x Priority - Task Heatmap | I102: Project | J102: Task | K102: Project Name | O102: Owner | P102: Type | R102: Budget | S102: Actual | T102: Overrun $ | V102: % Over
D103: High | E103: Medium | F103: Low | I103: P075 | J103: T001 | K103: Building a Park Project 075 | O103: Ivy | P103: Other | R103: 8493 | S103: 12398 | T103: =S103-R103 -> 3905 | V103: =(S103-R103)/R103 -> 0.45979042
C104: Behind | D104: =COUNTIFS(Dataset!$I$2:$I$301,$C104,Dataset!$J$2:$J$301,D$103) -> 45 | E104: =COUNTIFS(Dataset!$I$2:$I$301,$C104,Dataset!$J$2:$J$301,E$103) -> 27 | F104: =COUNTIFS(Dataset!$I$2:$I$301,$C104,Dataset!$J$2:$J$301,F$103) -> 15 | I104: P010 | J104: T001 | K104: Airport Expansion Project 010 | O104: Grace | P104: Other | R104: 1577 | S104: 4850 | T104: =S104-R104 -> 3273 | V104: =(S104-R104)/R104 -> 2.0754597
C105: On Track | D105: =COUNTIFS(Dataset!$I$2:$I$301,$C105,Dataset!$J$2:$J$301,D$103) -> 44 | E105: =COUNTIFS(Dataset!$I$2:$I$301,$C105,Dataset!$J$2:$J$301,E$103) -> 19 | F105: =COUNTIFS(Dataset!$I$2:$I$301,$C105,Dataset!$J$2:$J$301,F$103) -> 12 | I105: P096 | J105: T002 | K105: Office Building Renovation 096 | O105: Frank | P105: Renovation | R105: 2984 | S105: 6060 | T105: =S105-R105 -> 3076 | V105: =(S105-R105)/R105 -> 1.0308311
C106: On Hold | D106: =COUNTIFS(Dataset!$I$2:$I$301,$C106,Dataset!$J$2:$J$301,D$103) -> 30 | E106: =COUNTIFS(Dataset!$I$2:$I$301,$C106,Dataset!$J$2:$J$301,E$103) -> 17 | F106: =COUNTIFS(Dataset!$I$2:$I$301,$C106,Dataset!$J$2:$J$301,F$103) -> 13 | I106: P027 | J106: T002 | K106: University Dormitory Constr. 027 | O106: Bob | P106: Construction | R106: 1646 | S106: 4190 | T106: =S106-R106 -> 2544 | V106: =(S106-R106)/R106 -> 1.545565
C107: Completed | D107: =COUNTIFS(Dataset!$I$2:$I$301,$C107,Dataset!$J$2:$J$301,D$103) -> 37 | E107: =COUNTIFS(Dataset!$I$2:$I$301,$C107,Dataset!$J$2:$J$301,E$103) -> 28 | F107: =COUNTIFS(Dataset!$I$2:$I$301,$C107,Dataset!$J$2:$J$301,F$103) -> 13 | I107: P094 | J107: T003 | K107: Road Expansion Project 094 | O107: Charlie | P107: Infrastructure | R107: 1447 | S107: 3357 | T107: =S107-R107 -> 1910 | V107: =(S107-R107)/R107 -> 1.3199724
C108: Cell = task count; deeper red = higher concentration | I108: P052 | J108: T001 | K108: Apartment Complex Dev. 052 | O108: Ivy | P108: Other | R108: 8114 | S108: 9104 | T108: =S108-R108 -> 990 | V108: =(S108-R108)/R108 -> 0.12201134
I109: P022 | J109: T003 | K109: Apartment Complex Dev. 022 | O109: Ivy | P109: Other | R109: 1424 | S109: 2183 | T109: =S109-R109 -> 759 | V109: =(S109-R109)/R109 -> 0.53300562
C111: KEY INSIGHTS
C113: ▸ Spend is heavily back-loaded: only 30.7% of the $1.69M budget is committed to date, signalling an early-stage or schedule-delayed portfolio.
C114: ▸ Delivery risk is concentrated: 49 of 100 projects are Behind or On Hold, versus 26 Completed — nearly half the portfolio needs intervention.
C115: ▸ September 2024 is the spend peak at $148K (29% of all actual cost), worth investigating for cost spikes or milestone clustering.
C116: ▸ Workload is concentrated: Charlie and Alice carry 114 of 300 tasks (38%) and ~40% of logged hours — a key-person dependency risk.
C117: ▸ Cost control: 7 tasks are over budget by a combined $16.5K; High-priority items make up 52% of tasks, suggesting priority inflation.
C118: ▸ Overruns cluster in "Other" projects (4 of 7), led by Park P075 (+46%) and Airport P010 (+208%) - both warrant scope/estimate root-cause reviews before more cash is committed.
C119: ▸ Risk quadrant: "Other" ($555K) and "Renovation" ($395K) pair the largest budgets with the lowest average progress (~60-62%) - highest exposure, slowest burn.
C120: ▸ Resourcing is capacity-bound, not skill-bound: Frank leads on completion rate (44%) with the lightest load, while the two heaviest workloads (Charlie, Alice) sit near the portfolio-low ~26% - rebalancing should lift throughput.
C121: ▸ Schedule: average planned task duration is 148 days; Innovation runs longest (237 days), compounding its delivery risk and tying up budget for longer.
C122: ▸ Budget is geographically diversified - it takes ~10 of 13 states to reach 80% of spend - limiting single-location dependency but offering little vendor-consolidation leverage.

Sheet Data Model
B2: METRICS | E2: Project Status | F2: Projects | G2: % Share | I2: Project Type | J2: Projects | M2: Month | N2: Actual Cost | O2: Budget | Q2: Team Member | R2: Tasks | S2: Hours | T2: Budget Owned | V2: Location | W2: Actual Cost | X2: Budget | Y2: Tasks
B3: Metric | C3: Value | E3: Completed | F3: =COUNTIF(Dataset!$I$2:$I$301,E3)/3 -> 26 | G3: =F3/$C$4 -> 0.26 | I3: Renovation | J3: =COUNTIF(Dataset!$C$2:$C$301,I3)/3 -> 26 | M3: Feb-24 | N3: =SUMIF(Dataset!$H$2:$H$301,M3,Dataset!$Q$2:$Q$301) -> 27684 | O3: =SUMIF(Dataset!$H$2:$H$301,M3,Dataset!$P$2:$P$301) -> 38961 | Q3: Frank | R3: =COUNTIF(Dataset!$N$2:$N$301,Q3) -> 16 | S3: =SUMIF(Dataset!$N$2:$N$301,Q3,Dataset!$O$2:$O$301) -> 337 | T3: =SUMIF(Dataset!$N$2:$N$301,Q3,Dataset!$P$2:$P$301) -> 77055 | V3: Florida | W3: =SUMIF(Dataset!$D$2:$D$301,V3,Dataset!$Q$2:$Q$301) -> 20954 | X3: =SUMIF(Dataset!$D$2:$D$301,V3,Dataset!$P$2:$P$301) -> 103354 | Y3: =COUNTIF(Dataset!$D$2:$D$301,V3) -> 22
B4: Total Projects | C4: =SUMPRODUCT(1/COUNTIF(Dataset!$A$2:$A$301,Dataset!$A$2:$A$301)) -> 100 | E4: On Track | F4: =COUNTIF(Dataset!$I$2:$I$301,E4)/3 -> 25 | G4: =F4/$C$4 -> 0.25 | I4: Innovation | J4: =COUNTIF(Dataset!$C$2:$C$301,I4)/3 -> 7 | M4: Mar-24 | N4: =SUMIF(Dataset!$H$2:$H$301,M4,Dataset!$Q$2:$Q$301) -> 28256 | O4: =SUMIF(Dataset!$H$2:$H$301,M4,Dataset!$P$2:$P$301) -> 75357 | Q4: David | R4: =COUNTIF(Dataset!$N$2:$N$301,Q4) -> 26 | S4: =SUMIF(Dataset!$N$2:$N$301,Q4,Dataset!$O$2:$O$301) -> 436 | T4: =SUMIF(Dataset!$N$2:$N$301,Q4,Dataset!$P$2:$P$301) -> 129024 | V4: Washington | W4: =SUMIF(Dataset!$D$2:$D$301,V4,Dataset!$Q$2:$Q$301) -> 21153 | X4: =SUMIF(Dataset!$D$2:$D$301,V4,Dataset!$P$2:$P$301) -> 86123 | Y4: =COUNTIF(Dataset!$D$2:$D$301,V4) -> 16
B5: Total Tasks | C5: =COUNTA(Dataset!$K$2:$K$301) -> 300 | E5: Behind | F5: =COUNTIF(Dataset!$I$2:$I$301,E5)/3 -> 29 | G5: =F5/$C$4 -> 0.29 | I5: Construction | J5: =COUNTIF(Dataset!$C$2:$C$301,I5)/3 -> 20 | M5: Apr-24 | N5: =SUMIF(Dataset!$H$2:$H$301,M5,Dataset!$Q$2:$Q$301) -> 46333 | O5: =SUMIF(Dataset!$H$2:$H$301,M5,Dataset!$P$2:$P$301) -> 64913 | Q5: Bob | R5: =COUNTIF(Dataset!$N$2:$N$301,Q5) -> 25 | S5: =SUMIF(Dataset!$N$2:$N$301,Q5,Dataset!$O$2:$O$301) -> 473 | T5: =SUMIF(Dataset!$N$2:$N$301,Q5,Dataset!$P$2:$P$301) -> 145675 | V5: North Carolina | W5: =SUMIF(Dataset!$D$2:$D$301,V5,Dataset!$Q$2:$Q$301) -> 22793 | X5: =SUMIF(Dataset!$D$2:$D$301,V5,Dataset!$P$2:$P$301) -> 110002 | Y5: =COUNTIF(Dataset!$D$2:$D$301,V5) -> 21
B6: Total Budget | C6: =SUM(Dataset!$P$2:$P$301) -> 1687280 | E6: On Hold | F6: =COUNTIF(Dataset!$I$2:$I$301,E6)/3 -> 20 | G6: =F6/$C$4 -> 0.2 | I6: Infrastructure | J6: =COUNTIF(Dataset!$C$2:$C$301,I6)/3 -> 7 | M6: May-24 | N6: =SUMIF(Dataset!$H$2:$H$301,M6,Dataset!$Q$2:$Q$301) -> 43446 | O6: =SUMIF(Dataset!$H$2:$H$301,M6,Dataset!$P$2:$P$301) -> 73704 | Q6: Ivy | R6: =COUNTIF(Dataset!$N$2:$N$301,Q6) -> 39 | S6: =SUMIF(Dataset!$N$2:$N$301,Q6,Dataset!$O$2:$O$301) -> 608 | T6: =SUMIF(Dataset!$N$2:$N$301,Q6,Dataset!$P$2:$P$301) -> 228001 | V6: California | W6: =SUMIF(Dataset!$D$2:$D$301,V6,Dataset!$Q$2:$Q$301) -> 27162 | X6: =SUMIF(Dataset!$D$2:$D$301,V6,Dataset!$P$2:$P$301) -> 132003 | Y6: =COUNTIF(Dataset!$D$2:$D$301,V6) -> 23
B7: Actual Cost (Spent) | C7: =SUM(Dataset!$Q$2:$Q$301) -> 518421 | I7: Maintenance | J7: =COUNTIF(Dataset!$C$2:$C$301,I7)/3 -> 7 | M7: Jun-24 | N7: =SUMIF(Dataset!$H$2:$H$301,M7,Dataset!$Q$2:$Q$301) -> 51099 | O7: =SUMIF(Dataset!$H$2:$H$301,M7,Dataset!$P$2:$P$301) -> 98719 | Q7: Grace | R7: =COUNTIF(Dataset!$N$2:$N$301,Q7) -> 38 | S7: =SUMIF(Dataset!$N$2:$N$301,Q7,Dataset!$O$2:$O$301) -> 721 | T7: =SUMIF(Dataset!$N$2:$N$301,Q7,Dataset!$P$2:$P$301) -> 191912 | V7: New Jersey | W7: =SUMIF(Dataset!$D$2:$D$301,V7,Dataset!$Q$2:$Q$301) -> 32681 | X7: =SUMIF(Dataset!$D$2:$D$301,V7,Dataset!$P$2:$P$301) -> 117417 | Y7: =COUNTIF(Dataset!$D$2:$D$301,V7) -> 22
B8: Budget Utilization | C8: =C7/C6 -> 0.3072525 | I8: Other | J8: =COUNTIF(Dataset!$C$2:$C$301,I8)/3 -> 33 | M8: Jul-24 | N8: =SUMIF(Dataset!$H$2:$H$301,M8,Dataset!$Q$2:$Q$301) -> 84350 | O8: =SUMIF(Dataset!$H$2:$H$301,M8,Dataset!$P$2:$P$301) -> 209148 | Q8: Eve | R8: =COUNTIF(Dataset!$N$2:$N$301,Q8) -> 42 | S8: =SUMIF(Dataset!$N$2:$N$301,Q8,Dataset!$O$2:$O$301) -> 884 | T8: =SUMIF(Dataset!$N$2:$N$301,Q8,Dataset!$P$2:$P$301) -> 240784 | V8: New York | W8: =SUMIF(Dataset!$D$2:$D$301,V8,Dataset!$Q$2:$Q$301) -> 33397 | X8: =SUMIF(Dataset!$D$2:$D$301,V8,Dataset!$P$2:$P$301) -> 116224 | Y8: =COUNTIF(Dataset!$D$2:$D$301,V8) -> 21
B9: Avg Task Progress | C9: =AVERAGE(Dataset!$R$2:$R$301) -> 0.63606667 | E9: Task Status | F9: Tasks | G9: % Share | M9: Aug-24 | N9: =SUMIF(Dataset!$H$2:$H$301,M9,Dataset!$Q$2:$Q$301) -> 69500 | O9: =SUMIF(Dataset!$H$2:$H$301,M9,Dataset!$P$2:$P$301) -> 182429 | Q9: Alice | R9: =COUNTIF(Dataset!$N$2:$N$301,Q9) -> 54 | S9: =SUMIF(Dataset!$N$2:$N$301,Q9,Dataset!$O$2:$O$301) -> 1060 | T9: =SUMIF(Dataset!$N$2:$N$301,Q9,Dataset!$P$2:$P$301) -> 336554 | V9: Georgia | W9: =SUMIF(Dataset!$D$2:$D$301,V9,Dataset!$Q$2:$Q$301) -> 38636 | X9: =SUMIF(Dataset!$D$2:$D$301,V9,Dataset!$P$2:$P$301) -> 143498 | Y9: =COUNTIF(Dataset!$D$2:$D$301,V9) -> 29
B10: Total Hours Logged | C10: =SUM(Dataset!$O$2:$O$301) -> 5763 | E10: Completed | F10: =COUNTIF(Dataset!$M$2:$M$301,E10) -> 87 | G10: =F10/$C$5 -> 0.29 | M10: Sep-24 | N10: =SUMIF(Dataset!$H$2:$H$301,M10,Dataset!$Q$2:$Q$301) -> 148399 | O10: =SUMIF(Dataset!$H$2:$H$301,M10,Dataset!$P$2:$P$301) -> 205771 | Q10: Charlie | R10: =COUNTIF(Dataset!$N$2:$N$301,Q10) -> 60 | S10: =SUMIF(Dataset!$N$2:$N$301,Q10,Dataset!$O$2:$O$301) -> 1244 | T10: =SUMIF(Dataset!$N$2:$N$301,Q10,Dataset!$P$2:$P$301) -> 338275 | V10: Ohio | W10: =SUMIF(Dataset!$D$2:$D$301,V10,Dataset!$Q$2:$Q$301) -> 38934 | X10: =SUMIF(Dataset!$D$2:$D$301,V10,Dataset!$P$2:$P$301) -> 134056 | Y10: =COUNTIF(Dataset!$D$2:$D$301,V10) -> 23
B11: Over-Budget Tasks | C11: =SUMPRODUCT((Dataset!$Q$2:$Q$301>Dataset!$P$2:$P$301)*1) -> 7 | E11: In Progress | F11: =COUNTIF(Dataset!$M$2:$M$301,E11) -> 106 | G11: =F11/$C$5 -> 0.35333333 | I11: Project Type | J11: Budget | K11: Actual Cost | M11: Oct-24 | N11: =SUMIF(Dataset!$H$2:$H$301,M11,Dataset!$Q$2:$Q$301) -> 0 | O11: =SUMIF(Dataset!$H$2:$H$301,M11,Dataset!$P$2:$P$301) -> 60842 | V11: Texas | W11: =SUMIF(Dataset!$D$2:$D$301,V11,Dataset!$Q$2:$Q$301) -> 40831 | X11: =SUMIF(Dataset!$D$2:$D$301,V11,Dataset!$P$2:$P$301) -> 145497 | Y11: =COUNTIF(Dataset!$D$2:$D$301,V11) -> 22
B12: Completed Tasks | C12: =COUNTIF(Dataset!$M$2:$M$301,"Completed") -> 87 | E12: Pending | F12: =COUNTIF(Dataset!$M$2:$M$301,E12) -> 107 | G12: =F12/$C$5 -> 0.35666667 | I12: Renovation | J12: =SUMIF(Dataset!$C$2:$C$301,I12,Dataset!$P$2:$P$301) -> 395361 | K12: =SUMIF(Dataset!$C$2:$C$301,I12,Dataset!$Q$2:$Q$301) -> 121771 | M12: Nov-24 | N12: =SUMIF(Dataset!$H$2:$H$301,M12,Dataset!$Q$2:$Q$301) -> 0 | O12: =SUMIF(Dataset!$H$2:$H$301,M12,Dataset!$P$2:$P$301) -> 82297 | V12: Illinois | W12: =SUMIF(Dataset!$D$2:$D$301,V12,Dataset!$Q$2:$Q$301) -> 42351 | X12: =SUMIF(Dataset!$D$2:$D$301,V12,Dataset!$P$2:$P$301) -> 135609 | Y12: =COUNTIF(Dataset!$D$2:$D$301,V12) -> 20
B13: Completed Projects | C13: =COUNTIF(Dataset!$I$2:$I$301,"Completed")/3 -> 26 | I13: Innovation | J13: =SUMIF(Dataset!$C$2:$C$301,I13,Dataset!$P$2:$P$301) -> 115653 | K13: =SUMIF(Dataset!$C$2:$C$301,I13,Dataset!$Q$2:$Q$301) -> 37593 | M13: Dec-24 | N13: =SUMIF(Dataset!$H$2:$H$301,M13,Dataset!$Q$2:$Q$301) -> 0 | O13: =SUMIF(Dataset!$H$2:$H$301,M13,Dataset!$P$2:$P$301) -> 114337 | V13: Pennsylvania | W13: =SUMIF(Dataset!$D$2:$D$301,V13,Dataset!$Q$2:$Q$301) -> 61894 | X13: =SUMIF(Dataset!$D$2:$D$301,V13,Dataset!$P$2:$P$301) -> 127153 | Y13: =COUNTIF(Dataset!$D$2:$D$301,V13) -> 24
I14: Construction | J14: =SUMIF(Dataset!$C$2:$C$301,I14,Dataset!$P$2:$P$301) -> 377893 | K14: =SUMIF(Dataset!$C$2:$C$301,I14,Dataset!$Q$2:$Q$301) -> 124126 | M14: Jan-25 | N14: =SUMIF(Dataset!$H$2:$H$301,M14,Dataset!$Q$2:$Q$301) -> 6060 | O14: =SUMIF(Dataset!$H$2:$H$301,M14,Dataset!$P$2:$P$301) -> 61154 | V14: Michigan | W14: =SUMIF(Dataset!$D$2:$D$301,V14,Dataset!$Q$2:$Q$301) -> 65520 | X14: =SUMIF(Dataset!$D$2:$D$301,V14,Dataset!$P$2:$P$301) -> 150533 | Y14: =COUNTIF(Dataset!$D$2:$D$301,V14) -> 24
E15: Priority | F15: Tasks | G15: % Share | I15: Infrastructure | J15: =SUMIF(Dataset!$C$2:$C$301,I15,Dataset!$P$2:$P$301) -> 125426 | K15: =SUMIF(Dataset!$C$2:$C$301,I15,Dataset!$Q$2:$Q$301) -> 54186 | M15: Feb-25 | N15: =SUMIF(Dataset!$H$2:$H$301,M15,Dataset!$Q$2:$Q$301) -> 0 | O15: =SUMIF(Dataset!$H$2:$H$301,M15,Dataset!$P$2:$P$301) -> 50053 | V15: Virginia | W15: =SUMIF(Dataset!$D$2:$D$301,V15,Dataset!$Q$2:$Q$301) -> 72115 | X15: =SUMIF(Dataset!$D$2:$D$301,V15,Dataset!$P$2:$P$301) -> 185811 | Y15: =COUNTIF(Dataset!$D$2:$D$301,V15) -> 33
E16: High | F16: =COUNTIF(Dataset!$J$2:$J$301,E16) -> 156 | G16: =F16/$C$5 -> 0.52 | I16: Maintenance | J16: =SUMIF(Dataset!$C$2:$C$301,I16,Dataset!$P$2:$P$301) -> 117868 | K16: =SUMIF(Dataset!$C$2:$C$301,I16,Dataset!$Q$2:$Q$301) -> 35203 | M16: Mar-25 | N16: =SUMIF(Dataset!$H$2:$H$301,M16,Dataset!$Q$2:$Q$301) -> 4190 | O16: =SUMIF(Dataset!$H$2:$H$301,M16,Dataset!$P$2:$P$301) -> 92373
E17: Medium | F17: =COUNTIF(Dataset!$J$2:$J$301,E17) -> 91 | G17: =F17/$C$5 -> 0.30333333 | I17: Other | J17: =SUMIF(Dataset!$C$2:$C$301,I17,Dataset!$P$2:$P$301) -> 555079 | K17: =SUMIF(Dataset!$C$2:$C$301,I17,Dataset!$Q$2:$Q$301) -> 145542 | M17: Apr-25 | N17: =SUMIF(Dataset!$H$2:$H$301,M17,Dataset!$Q$2:$Q$301) -> 0 | O17: =SUMIF(Dataset!$H$2:$H$301,M17,Dataset!$P$2:$P$301) -> 72955
E18: Low | F18: =COUNTIF(Dataset!$J$2:$J$301,E18) -> 53 | G18: =F18/$C$5 -> 0.17666667 | M18: May-25 | N18: =SUMIF(Dataset!$H$2:$H$301,M18,Dataset!$Q$2:$Q$301) -> 0 | O18: =SUMIF(Dataset!$H$2:$H$301,M18,Dataset!$P$2:$P$301) -> 40492
M19: Jun-25 | N19: =SUMIF(Dataset!$H$2:$H$301,M19,Dataset!$Q$2:$Q$301) -> 0 | O19: =SUMIF(Dataset!$H$2:$H$301,M19,Dataset!$P$2:$P$301) -> 60409
I20: Project Type | J20: Avg Progress | M20: Jul-25 | N20: =SUMIF(Dataset!$H$2:$H$301,M20,Dataset!$Q$2:$Q$301) -> 9104 | O20: =SUMIF(Dataset!$H$2:$H$301,M20,Dataset!$P$2:$P$301) -> 25019
I21: Renovation | J21: =AVERAGEIF(Dataset!$C$2:$C$301,I21,Dataset!$R$2:$R$301) -> 0.59897436 | M21: Aug-25 | N21: =SUMIF(Dataset!$H$2:$H$301,M21,Dataset!$Q$2:$Q$301) -> 0 | O21: =SUMIF(Dataset!$H$2:$H$301,M21,Dataset!$P$2:$P$301) -> 24450
I22: Innovation | J22: =AVERAGEIF(Dataset!$C$2:$C$301,I22,Dataset!$R$2:$R$301) -> 0.6252381 | M22: Sep-25 | N22: =SUMIF(Dataset!$H$2:$H$301,M22,Dataset!$Q$2:$Q$301) -> 0 | O22: =SUMIF(Dataset!$H$2:$H$301,M22,Dataset!$P$2:$P$301) -> 37117
I23: Construction | J23: =AVERAGEIF(Dataset!$C$2:$C$301,I23,Dataset!$R$2:$R$301) -> 0.68033333 | M23: Oct-25 | N23: =SUMIF(Dataset!$H$2:$H$301,M23,Dataset!$Q$2:$Q$301) -> 0 | O23: =SUMIF(Dataset!$H$2:$H$301,M23,Dataset!$P$2:$P$301) -> 16780
I24: Infrastructure | J24: =AVERAGEIF(Dataset!$C$2:$C$301,I24,Dataset!$R$2:$R$301) -> 0.69238095
I25: Maintenance | J25: =AVERAGEIF(Dataset!$C$2:$C$301,I25,Dataset!$R$2:$R$301) -> 0.69428571
I26: Other | J26: =AVERAGEIF(Dataset!$C$2:$C$301,I26,Dataset!$R$2:$R$301) -> 0.61646465
B32: METRICS | E32: CUMULATIVE SPEND (S-CURVE) | K32: BUDGET PARETO — LOCATION | O32: RISK SEGMENTS BY TYPE | T32: PROGRESS DISTRIBUTION
B33: Portfolio CPI (billed) | C33: =SUMIFS(Dataset!$T$2:$T$301,Dataset!$W$2:$W$301,"Yes")/SUM(Dataset!$Q$2:$Q$301) -> 0.99750514 | E33: Month | F33: Actual | G33: Cum Actual | H33: Budget | I33: Cum Budget | K33: Location | L33: Budget | M33: Cumulative % | O33: Type | P33: Avg Progress | Q33: Budget | R33: Hours | T33: Completion Band | U33: Tasks
B34: Cost Variance (Favorable) | C34: =SUMIFS(Dataset!$P$2:$P$301,Dataset!$W$2:$W$301,"Yes")-SUM(Dataset!$Q$2:$Q$301) -> 5084 | E34: Feb-24 | F34: =SUMIF(Dataset!$H$2:$H$301,E34,Dataset!$Q$2:$Q$301) -> 27684 | G34: =SUM(F$32:F34) -> 27684 | H34: =SUMIF(Dataset!$H$2:$H$301,E34,Dataset!$P$2:$P$301) -> 38961 | I34: =SUM(H$32:H34) -> 38961 | K34: Virginia | L34: =SUMIF(Dataset!$D$2:$D$301,K34,Dataset!$P$2:$P$301) -> 185811 | M34: =SUM(L$32:L34)/SUM(L$32:L$44) -> 0.1240557 | O34: Renovation | P34: =AVERAGEIF(Dataset!$C$2:$C$301,O34,Dataset!$R$2:$R$301) -> 0.59897436 | Q34: =SUMIF(Dataset!$C$2:$C$301,O34,Dataset!$P$2:$P$301) -> 395361 | R34: =SUMIF(Dataset!$C$2:$C$301,O34,Dataset!$O$2:$O$301) -> 1600 | T34: 0-20% | U34: =COUNTIFS(Dataset!$R$2:$R$301,">=0",Dataset!$R$2:$R$301,"<0.2") -> 44
B35: Budget at Risk (Overruns) | C35: =SUM(Dataset!$V$2:$V$301) -> 16457 | E35: Mar-24 | F35: =SUMIF(Dataset!$H$2:$H$301,E35,Dataset!$Q$2:$Q$301) -> 28256 | G35: =SUM(F$32:F35) -> 55940 | H35: =SUMIF(Dataset!$H$2:$H$301,E35,Dataset!$P$2:$P$301) -> 75357 | I35: =SUM(H$32:H35) -> 114318 | K35: Michigan | L35: =SUMIF(Dataset!$D$2:$D$301,K35,Dataset!$P$2:$P$301) -> 150533 | M35: =SUM(L$32:L35)/SUM(L$32:L$44) -> 0.22455824 | O35: Innovation | P35: =AVERAGEIF(Dataset!$C$2:$C$301,O35,Dataset!$R$2:$R$301) -> 0.6252381 | Q35: =SUMIF(Dataset!$C$2:$C$301,O35,Dataset!$P$2:$P$301) -> 115653 | R35: =SUMIF(Dataset!$C$2:$C$301,O35,Dataset!$O$2:$O$301) -> 450 | T35: 20-40% | U35: =COUNTIFS(Dataset!$R$2:$R$301,">=0.2",Dataset!$R$2:$R$301,"<0.4") -> 41
B36: Avg Task Duration (Days) | C36: =AVERAGE(Dataset!$S$2:$S$301) -> 148.47 | E36: Apr-24 | F36: =SUMIF(Dataset!$H$2:$H$301,E36,Dataset!$Q$2:$Q$301) -> 46333 | G36: =SUM(F$32:F36) -> 102273 | H36: =SUMIF(Dataset!$H$2:$H$301,E36,Dataset!$P$2:$P$301) -> 64913 | I36: =SUM(H$32:H36) -> 179231 | K36: Texas | L36: =SUMIF(Dataset!$D$2:$D$301,K36,Dataset!$P$2:$P$301) -> 145497 | M36: =SUM(L$32:L36)/SUM(L$32:L$44) -> 0.32169851 | O36: Construction | P36: =AVERAGEIF(Dataset!$C$2:$C$301,O36,Dataset!$R$2:$R$301) -> 0.68033333 | Q36: =SUMIF(Dataset!$C$2:$C$301,O36,Dataset!$P$2:$P$301) -> 377893 | R36: =SUMIF(Dataset!$C$2:$C$301,O36,Dataset!$O$2:$O$301) -> 1089 | T36: 40-60% | U36: =COUNTIFS(Dataset!$R$2:$R$301,">=0.4",Dataset!$R$2:$R$301,"<0.6") -> 45
B37: Tasks Billed | C37: =COUNTIF(Dataset!$W$2:$W$301,"Yes") -> 93 | E37: May-24 | F37: =SUMIF(Dataset!$H$2:$H$301,E37,Dataset!$Q$2:$Q$301) -> 43446 | G37: =SUM(F$32:F37) -> 145719 | H37: =SUMIF(Dataset!$H$2:$H$301,E37,Dataset!$P$2:$P$301) -> 73704 | I37: =SUM(H$32:H37) -> 252935 | K37: Georgia | L37: =SUMIF(Dataset!$D$2:$D$301,K37,Dataset!$P$2:$P$301) -> 143498 | M37: =SUM(L$32:L37)/SUM(L$32:L$44) -> 0.41750417 | O37: Infrastructure | P37: =AVERAGEIF(Dataset!$C$2:$C$301,O37,Dataset!$R$2:$R$301) -> 0.69238095 | Q37: =SUMIF(Dataset!$C$2:$C$301,O37,Dataset!$P$2:$P$301) -> 125426 | R37: =SUMIF(Dataset!$C$2:$C$301,O37,Dataset!$O$2:$O$301) -> 436 | T37: 60-80% | U37: =COUNTIFS(Dataset!$R$2:$R$301,">=0.6",Dataset!$R$2:$R$301,"<0.8") -> 46
B38: On-Budget Rate | C38: =COUNTIFS(Dataset!$W$2:$W$301,"Yes",Dataset!$U$2:$U$301,"No")/COUNTIF(Dataset!W:W,"Yes") -> 0.92473118 | E38: Jun-24 | F38: =SUMIF(Dataset!$H$2:$H$301,E38,Dataset!$Q$2:$Q$301) -> 51099 | G38: =SUM(F$32:F38) -> 196818 | H38: =SUMIF(Dataset!$H$2:$H$301,E38,Dataset!$P$2:$P$301) -> 98719 | I38: =SUM(H$32:H38) -> 351654 | K38: Illinois | L38: =SUMIF(Dataset!$D$2:$D$301,K38,Dataset!$P$2:$P$301) -> 135609 | M38: =SUM(L$32:L38)/SUM(L$32:L$44) -> 0.50804278 | O38: Maintenance | P38: =AVERAGEIF(Dataset!$C$2:$C$301,O38,Dataset!$R$2:$R$301) -> 0.69428571 | Q38: =SUMIF(Dataset!$C$2:$C$301,O38,Dataset!$P$2:$P$301) -> 117868 | R38: =SUMIF(Dataset!$C$2:$C$301,O38,Dataset!$O$2:$O$301) -> 454 | T38: 80-99% | U38: =COUNTIFS(Dataset!$R$2:$R$301,">=0.8",Dataset!$R$2:$R$301,"<1") -> 36
B39: Task Completion Rate | C39: =COUNTIF(Dataset!$M$2:$M$301,"Completed")/COUNTA(Dataset!$K$2:$K$301) -> 0.29 | E39: Jul-24 | F39: =SUMIF(Dataset!$H$2:$H$301,E39,Dataset!$Q$2:$Q$301) -> 84350 | G39: =SUM(F$32:F39) -> 281168 | H39: =SUMIF(Dataset!$H$2:$H$301,E39,Dataset!$P$2:$P$301) -> 209148 | I39: =SUM(H$32:H39) -> 560802 | K39: Ohio | L39: =SUMIF(Dataset!$D$2:$D$301,K39,Dataset!$P$2:$P$301) -> 134056 | M39: =SUM(L$32:L39)/SUM(L$32:L$44) -> 0.59754454 | O39: Other | P39: =AVERAGEIF(Dataset!$C$2:$C$301,O39,Dataset!$R$2:$R$301) -> 0.61646465 | Q39: =SUMIF(Dataset!$C$2:$C$301,O39,Dataset!$P$2:$P$301) -> 555079 | R39: =SUMIF(Dataset!$C$2:$C$301,O39,Dataset!$O$2:$O$301) -> 1734 | T39: 100% | U39: =COUNTIF(Dataset!$R$2:$R$301,1) -> 88
B40: Total Earned Value | C40: =SUM(Dataset!$T$2:$T$301) -> 1085090.2 | E40: Aug-24 | F40: =SUMIF(Dataset!$H$2:$H$301,E40,Dataset!$Q$2:$Q$301) -> 69500 | G40: =SUM(F$32:F40) -> 350668 | H40: =SUMIF(Dataset!$H$2:$H$301,E40,Dataset!$P$2:$P$301) -> 182429 | I40: =SUM(H$32:H40) -> 743231 | K40: California | L40: =SUMIF(Dataset!$D$2:$D$301,K40,Dataset!$P$2:$P$301) -> 132003 | M40: =SUM(L$32:L40)/SUM(L$32:L$44) -> 0.68567562
E41: Sep-24 | F41: =SUMIF(Dataset!$H$2:$H$301,E41,Dataset!$Q$2:$Q$301) -> 148399 | G41: =SUM(F$32:F41) -> 499067 | H41: =SUMIF(Dataset!$H$2:$H$301,E41,Dataset!$P$2:$P$301) -> 205771 | I41: =SUM(H$32:H41) -> 949002 | K41: Pennsylvania | L41: =SUMIF(Dataset!$D$2:$D$301,K41,Dataset!$P$2:$P$301) -> 127153 | M41: =SUM(L$32:L41)/SUM(L$32:L$44) -> 0.77056863
E42: Oct-24 | F42: =SUMIF(Dataset!$H$2:$H$301,E42,Dataset!$Q$2:$Q$301) -> 0 | G42: =SUM(F$32:F42) -> 499067 | H42: =SUMIF(Dataset!$H$2:$H$301,E42,Dataset!$P$2:$P$301) -> 60842 | I42: =SUM(H$32:H42) -> 1009844 | K42: New Jersey | L42: =SUMIF(Dataset!$D$2:$D$301,K42,Dataset!$P$2:$P$301) -> 117417 | M42: =SUM(L$32:L42)/SUM(L$32:L$44) -> 0.84896145
E43: Nov-24 | F43: =SUMIF(Dataset!$H$2:$H$301,E43,Dataset!$Q$2:$Q$301) -> 0 | G43: =SUM(F$32:F43) -> 499067 | H43: =SUMIF(Dataset!$H$2:$H$301,E43,Dataset!$P$2:$P$301) -> 82297 | I43: =SUM(H$32:H43) -> 1092141 | K43: New York | L43: =SUMIF(Dataset!$D$2:$D$301,K43,Dataset!$P$2:$P$301) -> 116224 | M43: =SUM(L$32:L43)/SUM(L$32:L$44) -> 0.92655776
E44: Dec-24 | F44: =SUMIF(Dataset!$H$2:$H$301,E44,Dataset!$Q$2:$Q$301) -> 0 | G44: =SUM(F$32:F44) -> 499067 | H44: =SUMIF(Dataset!$H$2:$H$301,E44,Dataset!$P$2:$P$301) -> 114337 | I44: =SUM(H$32:H44) -> 1206478 | K44: North Carolina | L44: =SUMIF(Dataset!$D$2:$D$301,K44,Dataset!$P$2:$P$301) -> 110002 | M44: =SUM(L$32:L44)/SUM(L$32:L$44) -> 1
E45: Jan-25 | F45: =SUMIF(Dataset!$H$2:$H$301,E45,Dataset!$Q$2:$Q$301) -> 6060 | G45: =SUM(F$32:F45) -> 505127 | H45: =SUMIF(Dataset!$H$2:$H$301,E45,Dataset!$P$2:$P$301) -> 61154 | I45: =SUM(H$32:H45) -> 1267632 | K45: Florida | L45: =SUMIF(Dataset!$D$2:$D$301,K45,Dataset!$P$2:$P$301) -> 103354 | M45: =SUM(L$32:L45)/SUM(L$32:L$44) -> 1.0690037
E46: Feb-25 | F46: =SUMIF(Dataset!$H$2:$H$301,E46,Dataset!$Q$2:$Q$301) -> 0 | G46: =SUM(F$32:F46) -> 505127 | H46: =SUMIF(Dataset!$H$2:$H$301,E46,Dataset!$P$2:$P$301) -> 50053 | I46: =SUM(H$32:H46) -> 1317685 | K46: Washington | L46: =SUMIF(Dataset!$D$2:$D$301,K46,Dataset!$P$2:$P$301) -> 86123 | M46: =SUM(L$32:L46)/SUM(L$32:L$44) -> 1.1265033
...

Sheet Dataset
A1: Project ID | B1: Project Name | C1: Project Type | D1: Location | E1: Start Date | F1: End Date | G1: Month | H1: Month Name | I1: Project Status | J1: Priority | K1: Task ID | L1: Task Name | M1: Task Status | N1: Assigned To | O1: Hours Spent | P1: Budget | Q1: Actual Cost | R1: Progress | S1: Duration (Days) | T1: Earned Value | U1: Over Budget? | V1: Overrun $ | W1: Billed?
A2: P001 | B2: Renovation of a School Project 001 | C2: Renovation | D2: Texas | E2: 45494 | F2: 45512 | G2: 45505 | H2: Aug-24 | I2: Behind | J2: Medium | K2: T001 | L2: Task 001 of Renovation of a School Project 001 | M2: In Progress | N2: Bob | O2: 12 | P2: 9621 | Q2: 0 | R2: 0.24 | S2: =F2-E2 -> 18 | T2: =R2*P2 -> 2309.04 | U2: =IF(AND(Q2>0,Q2>P2),"Yes","No") -> No | V2: =IF(U2="Yes",Q2-P2,0) -> 0 | W2: =IF(Q2>0,"Yes","No") -> No
A3: P001 | B3: Renovation of a School Project 001 | C3: Renovation | D3: New Jersey | E3: 45494 | F3: 45516 | G3: 45505 | H3: Aug-24 | I3: Behind | J3: High | K3: T002 | L3: Task 002 of Renovation of a School Project 001 | M3: In Progress | N3: Charlie | O3: 4 | P3: 7814 | Q3: 0 | R3: 0.56 | S3: =F3-E3 -> 22 | T3: =R3*P3 -> 4375.84 | U3: =IF(AND(Q3>0,Q3>P3),"Yes","No") -> No | V3: =IF(U3="Yes",Q3-P3,0) -> 0 | W3: =IF(Q3>0,"Yes","No") -> No
A4: P001 | B4: Renovation of a School Project 001 | C4: Renovation | D4: Ohio | E4: 45494 | F4: 45514 | G4: 45505 | H4: Aug-24 | I4: Behind | J4: High | K4: T003 | L4: Task 003 of Renovation of a School Project 001 | M4: Completed | N4: Charlie | O4: 5 | P4: 1028 | Q4: 1011 | R4: 1 | S4: =F4-E4 -> 20 | T4: =R4*P4 -> 1028 | U4: =IF(AND(Q4>0,Q4>P4),"Yes","No") -> No | V4: =IF(U4="Yes",Q4-P4,0) -> 0 | W4: =IF(Q4>0,"Yes","No") -> Yes
A5: P002 | B5: Innovation of a Classroom Project 002 | C5: Innovation | D5: Pennsylvania | E5: 45388 | F5: 45850 | G5: 45839 | H5: Jul-25 | I5: On Track | J5: High | K5: T001 | L5: Task 001 of Innovation of a Classroom Project 002 | M5: Pending | N5: Charlie | O5: 24 | P5: 1530 | Q5: 0 | R5: 0.33 | S5: =F5-E5 -> 462 | T5: =R5*P5 -> 504.9 | U5: =IF(AND(Q5>0,Q5>P5),"Yes","No") -> No | V5: =IF(U5="Yes",Q5-P5,0) -> 0 | W5: =IF(Q5>0,"Yes","No") -> No
A6: P002 | B6: Innovation of a Classroom Project 002 | C6: Innovation | D6: New York | E6: 45388 | F6: 45834 | G6: 45809 | H6: Jun-25 | I6: On Track | J6: Medium | K6: T002 | L6: Task 002 of Innovation of a Classroom Project 002 | M6: Pending | N6: Charlie | O6: 26 | P6: 7201 | Q6: 0 | R6: 0.32 | S6: =F6-E6 -> 446 | T6: =R6*P6 -> 2304.32 | U6: =IF(AND(Q6>0,Q6>P6),"Yes","No") -> No | V6: =IF(U6="Yes",Q6-P6,0) -> 0 | W6: =IF(Q6>0,"Yes","No") -> No
A7: P002 | B7: Innovation of a Classroom Project 002 | C7: Innovation | D7: California | E7: 45388 | F7: 45741 | G7: 45717 | H7: Mar-25 | I7: On Track | J7: Low | K7: T003 | L7: Task 003 of Innovation of a Classroom Project 002 | M7: In Progress | N7: Alice | O7: 28 | P7: 9814 | Q7: 0 | R7: 0.29 | S7: =F7-E7 -> 353 | T7: =R7*P7 -> 2846.06 | U7: =IF(AND(Q7>0,Q7>P7),"Yes","No") -> No | V7: =IF(U7="Yes",Q7-P7,0) -> 0 | W7: =IF(Q7>0,"Yes","No") -> No
A8: P003 | B8: Construction of a Hospital Wing Project 003 | C8: Construction | D8: Pennsylvania | E8: 45493 | F8: 45526 | G8: 45505 | H8: Aug-24 | I8: Completed | J8: Low | K8: T001 | L8: Task 001 of Construction of a Hospital Wing Project 003 | M8: Completed | N8: Grace | O8: 7 | P8: 7981 | Q8: 7717 | R8: 1 | S8: =F8-E8 -> 33 | T8: =R8*P8 -> 7981 | U8: =IF(AND(Q8>0,Q8>P8),"Yes","No") -> No | V8: =IF(U8="Yes",Q8-P8,0) -> 0 | W8: =IF(Q8>0,"Yes","No") -> Yes
A9: P003 | B9: Construction of a Hospital Wing Project 003 | C9: Construction | D9: Virginia | E9: 45493 | F9: 45560 | G9: 45536 | H9: Sep-24 | I9: Completed | J9: Medium | K9: T002 | L9: Task 002 of Construction of a Hospital Wing Project 003 | M9: Completed | N9: Frank | O9: 23 | P9: 1032 | Q9: 637 | R9: 1 | S9: =F9-E9 -> 67 | T9: =R9*P9 -> 1032 | U9: =IF(AND(Q9>0,Q9>P9),"Yes","No") -> No | V9: =IF(U9="Yes",Q9-P9,0) -> 0 | W9: =IF(Q9>0,"Yes","No") -> Yes
A10: P003 | B10: Construction of a Hospital Wing Project 003 | C10: Construction | D10: Ohio | E10: 45493 | F10: 45526 | G10: 45505 | H10: Aug-24 | I10: Completed | J10: Medium | K10: T003 | L10: Task 003 of Construction of a Hospital Wing Project 003 | M10: Completed | N10: Grace | O10: 13 | P10: 8546 | Q10: 8502 | R10: 1 | S10: =F10-E10 -> 33 | T10: =R10*P10 -> 8546 | U10: =IF(AND(Q10>0,Q10>P10),"Yes","No") -> No | V10: =IF(U10="Yes",Q10-P10,0) -> 0 | W10: =IF(Q10>0,"Yes","No") -> Yes
A11: P004 | B11: Road Expansion Project 004 | C11: Infrastructure | D11: Pennsylvania | E11: 45407 | F11: 45418 | G11: 45413 | H11: May-24 | I11: Completed | J11: Medium | K11: T001 | L11: Task 001 of Road Expansion Project 004 | M11: Completed | N11: Frank | O11: 28 | P11: 3728 | Q11: 3369 | R11: 1 | S11: =F11-E11 -> 11 | T11: =R11*P11 -> 3728 | U11: =IF(AND(Q11>0,Q11>P11),"Yes","No") -> No | V11: =IF(U11="Yes",Q11-P11,0) -> 0 | W11: =IF(Q11>0,"Yes","No") -> Yes
A12: P004 | B12: Road Expansion Project 004 | C12: Infrastructure | D12: Texas | E12: 45407 | F12: 45417 | G12: 45413 | H12: May-24 | I12: Completed | J12: High | K12: T002 | L12: Task 002 of Road Expansion Project 004 | M12: In Progress | N12: Charlie | O12: 26 | P12: 9707 | Q12: 0 | R12: 0.99 | S12: =F12-E12 -> 10 | T12: =R12*P12 -> 9609.93 | U12: =IF(AND(Q12>0,Q12>P12),"Yes","No") -> No | V12: =IF(U12="Yes",Q12-P12,0) -> 0 | W12: =IF(Q12>0,"Yes","No") -> No
A13: P004 | B13: Road Expansion Project 004 | C13: Infrastructure | D13: Texas | E13: 45407 | F13: 45422 | G13: 45413 | H13: May-24 | I13: Completed | J13: Medium | K13: T003 | L13: Task 003 of Road Expansion Project 004 | M13: Pending | N13: Charlie | O13: 18 | P13: 5712 | Q13: 0 | R13: 0.74 | S13: =F13-E13 -> 15 | T13: =R13*P13 -> 4226.88 | U13: =IF(AND(Q13>0,Q13>P13),"Yes","No") -> No | V13: =IF(U13="Yes",Q13-P13,0) -> 0 | W13: =IF(Q13>0,"Yes","No") -> No
... A301: P100 | B301: Airport Expansion Project 100 | C301: Other | D301: Virginia | E301: 45512 | F301: 45534 | G301: 45505 | H301: Aug-24 | I301: On Track | J301: Medium | K301: T003 | L301: Task 003 of Airport Expansion Project 100 | M301: In Progress | N301: Alice | O301: 38 | P301: 8619 | Q301: 0 | R301: 0.86 | S301: =F301-E301 -> 22 | T301: =R301*P301 -> 7412.34 | U301: =IF(AND(Q301>0,Q301>P301),"Yes","No") -> No | V301: =IF(U301="Yes",Q301-P301,0) -> 0 | W301: =IF(Q301>0,"Yes","No") -> No
